<?xml version='1.0'?>
<sdf version='1.4'>
  <model name='puzzlebot1' canonical_link='chassis'>

    <!-- Chassis -->
    <link name='chassis'>
      <pose relative_to='__model__'>0 0 0.05 0 0 0</pose>
      
      <inertial>
        <mass>1.0</mass>
        <pose>-0.05 0 -0.01 0 0 0</pose>
        <inertia>
          <ixx>0.004</ixx>
          <iyy>0.004</iyy>
          <izz>0.004</izz>
          <ixy>0</ixy>
          <ixz>0</ixz>
          <iyz>0</iyz>
        </inertia>
      </inertial>
      
      <visual name='visual'>
        <geometry>
          <mesh>
            <uri>file:///home/idmx/ros2_ws_2/src/motor_control/puzzlebot/meshes/chassis1.dae</uri>
          </mesh>
        </geometry>
        <!-- Material para el chasis (se mantiene rojo, pero puedes cambiarlo) -->
        <material>
          <ambient>1 0 0 1</ambient>
          <diffuse>1 0 0 1</diffuse>
          <specular>0.5 0.5 0.5 1</specular>
        </material>
      </visual>
      
      <collision name='collision'>
        <pose>-0.055 0 0 0 0 0</pose>
        <geometry>
          <box>
            <size>0.2 0.16 0.046</size>
          </box>
        </geometry>
      </collision>
      
    </link>

    <!-- Right wheel -->
    <link name='right_wheel'>
      <!-- Se baja la rueda en z para que toque el suelo -->
      <pose relative_to="chassis">0.0 -0.095 -0.02 0 0 3.1415</pose>
      
      <inertial>
        <mass>0.05</mass>
        <inertia>
          <ixx>0.002</ixx>
          <iyy>0.002</iyy>
          <izz>0.002</izz>
          <ixy>0</ixy>
          <ixz>0</ixz>
          <iyz>0</iyz>
        </inertia>
      </inertial>
      
      <!-- Visual: rueda en cilindro aplanado en gris oscuro -->
      <visual name='visual'>
      	<pose>0 0 0 -1.5708 0 0</pose>
        <geometry>
          <cylinder>
            <radius>0.05</radius>
            <length>0.005</length>
          </cylinder>
        </geometry>
        <material>
          <ambient>0.2 0.2 0.2 1</ambient>
          <diffuse>0.2 0.2 0.2 1</diffuse>
          <specular>0.1 0.1 0.1 1</specular>
        </material>
      </visual>
      
      <collision name='collision'>
        <pose>0 -0.0025 0 1.5707 0 0</pose>
        <geometry>
          <cylinder>
            <radius>0.05</radius>
            <length>0.005</length>
          </cylinder>
        </geometry>
        <surface>
          <friction>
            <ode>
              <mu>1.0</mu>
              <mu2>1.0</mu2>
            </ode>
          </friction>
        </surface>
      </collision>
      
    </link>

    <!-- Left wheel -->
    <link name='left_wheel'>
      <!-- Se baja la rueda en z para que toque el suelo -->
      <pose relative_to="chassis">0.0 0.095 -0.02 0 0 0</pose>
      
      <inertial>
        <mass>0.05</mass>
        <inertia>
          <ixx>0.002</ixx>
          <iyy>0.002</iyy>
          <izz>0.002</izz>
          <ixy>0</ixy>
          <ixz>0</ixz>
          <iyz>0</iyz>
        </inertia>
      </inertial>
      
      <!-- Visual: rueda en cilindro aplanado en gris oscuro -->
      <visual name='visual'>
      	<pose>0 0 0 -1.5708 0 0</pose>
        <geometry>
          <cylinder>
            <radius>0.05</radius>
            <length>0.005</length>
          </cylinder>
        </geometry>
        <material>
          <ambient>0.2 0.2 0.2 1</ambient>
          <diffuse>0.2 0.2 0.2 1</diffuse>
          <specular>0.1 0.1 0.1 1</specular>
        </material>
      </visual>
      
      <collision name='collision'>
        <pose>0 -0.0025 0 1.5707 0 0</pose>
        <geometry>
          <cylinder>
            <radius>0.05</radius>
            <length>0.005</length>
          </cylinder>
        </geometry>
        <surface>
          <friction>
            <ode>
              <mu>1.0</mu>
              <mu2>1.0</mu2>
            </ode>
          </friction>
        </surface>
      </collision>
      
    </link>

    <!-- Arbitrary frame para el caster -->
    <frame name="caster_frame" attached_to='chassis'>
      <pose>-0.145 0 -0.044 0 0 0</pose>
    </frame>

    <!-- Caster wheel -->
    <link name='caster'>
      <pose relative_to='caster_frame'/>
      
      <inertial>
        <mass>0.01</mass>
        <inertia>
          <ixx>0.0000025</ixx>
          <iyy>0.0000025</iyy>
          <izz>0.0000025</izz>
          <ixy>0</ixy>
          <ixz>0</ixz>
          <iyz>0</iyz>
        </inertia>
      </inertial>
      
      <visual name='visual'>
        <geometry>
          <sphere>
            <radius>0.006</radius>
          </sphere>
        </geometry>
        <material>
          <!-- Caster en negro -->
          <ambient>0 0 0 1</ambient>
          <diffuse>0 0 0 1</diffuse>
          <specular>0.1 0.1 0.1 1</specular>
        </material>
      </visual>
      
      <collision name='collision'>
        <geometry>
          <sphere>
            <radius>0.006</radius>
          </sphere>
        </geometry>
      </collision>
    </link>

    <!-- Joint: Left Wheel -->
    <joint name='left_wheel_joint' type='revolute'>
      <pose relative_to='left_wheel'/>
      <parent>chassis</parent>
      <child>left_wheel</child>
      <axis>
        <xyz expressed_in='__model__'>0 1 0</xyz>
        <limit>
          <lower>-1.79769e+308</lower>
          <upper>1.79769e+308</upper>
          <effort>1</effort>
        </limit>
        <dynamics>
          <friction>0.1</friction>
        </dynamics>
      </axis>
    </joint>

    <!-- Joint: Right Wheel -->
    <joint name='right_wheel_joint' type='revolute'>
      <pose relative_to='right_wheel'/>
      <parent>chassis</parent>
      <child>right_wheel</child>
      <axis>
        <xyz expressed_in='__model__'>0 1 0</xyz>
        <limit>
          <lower>-1.79769e+308</lower>
          <upper>1.79769e+308</upper>
          <effort>1</effort>
        </limit>
        <dynamics>
          <friction>0.1</friction>
        </dynamics>
      </axis>
    </joint>

    <!-- Joint: Caster Wheel -->
    <joint name='caster_wheel' type='ball'>
      <parent>chassis</parent>
      <child>caster</child>
    </joint>

    <!-- Plugin de Differential Drive de Gazebo ROS -->
    <plugin name="gazebo_ros_diff_drive" filename="libgazebo_ros_diff_drive.so">
      <ros>
        <namespace>/puzzlebot</namespace>
        <argument>cmd_vel</argument>
      </ros>
      <update_rate>100</update_rate>
      <wheel_separation>0.19</wheel_separation>
      <wheel_diameter>0.1</wheel_diameter>
      <torque>5</torque>
      <left_joint>left_wheel_joint</left_joint>
      <right_joint>right_wheel_joint</right_joint>
      <command_topic>cmd_vel</command_topic>
      <odometry_topic>odom</odometry_topic>
      <odometry_frame>odom</odometry_frame>
      <robot_base_frame>chassis</robot_base_frame>
    </plugin>
                
  </model>
</sdf>

